{
 "cells": [
  {
   "cell_type": "markdown",
   "metadata": {},
   "source": [
    "<!--BOOK_INFORMATION-->\n",
    "<img align=\"left\" style=\"padding-right:10px;\" src=\"img/cover-small.jpg\" />\n",
    "\n",
    "Dieses Notizbuch enthält einen angepassten Auszug aus der [Whirlwind Tour of Python](http://www.oreilly.com/programming/free/a-whirlwind-tour-of-python.csp) von Jake VanderPlas; Der Inhalt ist auf [GitHub](https://github.com/jakevdp/WhirlwindTourOfPython) verfügbar.\n",
    "\n",
    "Text und Code werden unter der [CC0](https://github.com/jakevdp/WhirlwindTourOfPython/blob/master/LICENSE)- Lizenz veröffentlicht; Das Begleitprojekt, das [Python Data Science Handbook](https://github.com/jakevdp/PythonDataScienceHandbook) wird sehr empfohlen.\n"
   ]
  },
  {
   "cell_type": "markdown",
   "metadata": {},
   "source": [
    "# Fehler und Ausnahmen (Errors and Exceptions)"
   ]
  },
  {
   "cell_type": "markdown",
   "metadata": {},
   "source": [
    "Unabhängig von unseren Fähigkeiten als Programmierer:innen werden wir früher oder später einen Programmierfehler machen.\n",
    "\n",
    "Wir unterscheiden grundsätzlich drei Varianten:\n",
    "\n",
    "- *Syntaxfehler:* Fehler, bei denen der Code kein gültiger Python-Code ist (im Allgemeinen leicht zu beheben)\n",
    "- *Laufzeitfehler:* Fehler, bei denen syntaktisch gültiger Code nicht ausgeführt werden kann, vielleicht aufgrund ungültiger Benutzereingaben (manchmal leicht zu beheben)\n",
    "- *Semantische Fehler:* Fehler in der Logik: Der Code wird problemlos ausgeführt, aber das Ergebnis ist nicht das, was Sie erwarten (oft sehr schwer aufzuspüren und zu beheben)\n",
    "\n",
    "Wir werden uns darauf konzentrieren, wie man mit *Laufzeitfehlern* sauber umgeht. Wie wir sehen werden, behandelt Python Laufzeitfehler über das integrierte Framework zur *Ausnahmebehandlung*."
   ]
  },
  {
   "cell_type": "markdown",
   "metadata": {},
   "source": [
    "## Laufzeitfehler\n",
    "\n",
    "Alle, die schon einmal in Python programmiert haben, sind wahrscheinlich schon auf Laufzeitfehler gestoßen. Sie können auf verschiedene Arten auftreten.\n",
    "\n",
    "Zum Beispiel, wenn wir versuchen, eine undefinierte Variable zu referenzieren:"
   ]
  },
  {
   "cell_type": "code",
   "execution_count": 1,
   "metadata": {
    "collapsed": false
   },
   "outputs": [
    {
     "ename": "NameError",
     "evalue": "name 'Q' is not defined",
     "output_type": "error",
     "traceback": [
      "\u001b[0;31m---------------------------------------------------------------------------\u001b[0m",
      "\u001b[0;31mNameError\u001b[0m                                 Traceback (most recent call last)",
      "Cell \u001b[0;32mIn[1], line 1\u001b[0m\n\u001b[0;32m----> 1\u001b[0m \u001b[38;5;28mprint\u001b[39m(\u001b[43mQ\u001b[49m)\n",
      "\u001b[0;31mNameError\u001b[0m: name 'Q' is not defined"
     ]
    }
   ],
   "source": [
    "print(Q)"
   ]
  },
  {
   "cell_type": "markdown",
   "metadata": {},
   "source": [
    "Oder wenn wir eine Operation ausprobieren, die nicht definiert ist:"
   ]
  },
  {
   "cell_type": "code",
   "execution_count": 2,
   "metadata": {
    "collapsed": false
   },
   "outputs": [
    {
     "data": {
      "text/plain": [
       "'1abc'"
      ]
     },
     "execution_count": 2,
     "metadata": {},
     "output_type": "execute_result"
    }
   ],
   "source": [
    "1 + 'abc'"
   ]
  },
  {
   "cell_type": "markdown",
   "metadata": {},
   "source": [
    "Oder wir versuchen, ein mathematisch unbestimmtes Ergebnis zu berechnen:"
   ]
  },
  {
   "cell_type": "code",
   "execution_count": 5,
   "metadata": {
    "collapsed": false
   },
   "outputs": [
    {
     "ename": "ZeroDivisionError",
     "evalue": "division by zero",
     "output_type": "error",
     "traceback": [
      "\u001b[0;31m---------------------------------------------------------------------------\u001b[0m",
      "\u001b[0;31mZeroDivisionError\u001b[0m                         Traceback (most recent call last)",
      "\u001b[0;32m<ipython-input-5-ae0c5d243292>\u001b[0m in \u001b[0;36m<module>\u001b[0;34m()\u001b[0m\n\u001b[0;32m----> 1\u001b[0;31m \u001b[0;36m2\u001b[0m \u001b[0;34m/\u001b[0m \u001b[0;36m0\u001b[0m\u001b[0;34m\u001b[0m\u001b[0m\n\u001b[0m",
      "\u001b[0;31mZeroDivisionError\u001b[0m: division by zero"
     ]
    }
   ],
   "source": [
    "2 / 0"
   ]
  },
  {
   "cell_type": "markdown",
   "metadata": {},
   "source": [
    "Oder vielleicht versuchen wir, auf ein Sequenzelement zuzugreifen, das nicht existiert:"
   ]
  },
  {
   "cell_type": "code",
   "execution_count": 6,
   "metadata": {
    "collapsed": false
   },
   "outputs": [
    {
     "ename": "IndexError",
     "evalue": "list index out of range",
     "output_type": "error",
     "traceback": [
      "\u001b[0;31m---------------------------------------------------------------------------\u001b[0m",
      "\u001b[0;31mIndexError\u001b[0m                                Traceback (most recent call last)",
      "\u001b[0;32m<ipython-input-6-06b6eb1b8957>\u001b[0m in \u001b[0;36m<module>\u001b[0;34m()\u001b[0m\n\u001b[1;32m      1\u001b[0m \u001b[0mL\u001b[0m \u001b[0;34m=\u001b[0m \u001b[0;34m[\u001b[0m\u001b[0;36m1\u001b[0m\u001b[0;34m,\u001b[0m \u001b[0;36m2\u001b[0m\u001b[0;34m,\u001b[0m \u001b[0;36m3\u001b[0m\u001b[0;34m]\u001b[0m\u001b[0;34m\u001b[0m\u001b[0m\n\u001b[0;32m----> 2\u001b[0;31m \u001b[0mL\u001b[0m\u001b[0;34m[\u001b[0m\u001b[0;36m1000\u001b[0m\u001b[0;34m]\u001b[0m\u001b[0;34m\u001b[0m\u001b[0m\n\u001b[0m",
      "\u001b[0;31mIndexError\u001b[0m: list index out of range"
     ]
    }
   ],
   "source": [
    "L = [1, 2, 3]\n",
    "L[1000]"
   ]
  },
  {
   "cell_type": "markdown",
   "metadata": {},
   "source": [
    "Wir können erkennen, dass Python in jedem Fall so freundlich ist, nicht einfach anzuzeigen, dass ein Fehler aufgetreten ist. Wir erhalten eine *aussagekräftige* Fehlermeldung, die Informationen darüber enthält, was genau schiefgelaufen ist, zusammen mit der exakten Codezeile, in der der Fehler aufgetreten ist.\n",
    "\n",
    "Der Zugriff auf aussagekräftige Fehlermeldungen wie diese ist ungemein nützlich, wenn man versucht, die Ursache von Problemen in seinem Code zu finden."
   ]
  },
  {
   "cell_type": "markdown",
   "metadata": {},
   "source": [
    "## Ausnahmen fangen: ``try`` und ``except``\n",
    "Das wichtigste Werkzeug, das Python uns für die Behandlung von Laufzeitausnahmen zur Verfügung stellt, ist die \n",
    "\n",
    " The main tool Python gives you for handling runtime exceptions is the ``try``...``except`` Klausel.\n",
    "\n",
    "Die Grundstruktur dabei sieht so aus:"
   ]
  },
  {
   "cell_type": "code",
   "execution_count": 3,
   "metadata": {
    "collapsed": false
   },
   "outputs": [
    {
     "name": "stdout",
     "output_type": "stream",
     "text": [
      "this gets executed first\n"
     ]
    }
   ],
   "source": [
    "try:\n",
    "    print(\"this gets executed first\")\n",
    "except:\n",
    "    print(\"this gets executed only if there is an error\")"
   ]
  },
  {
   "cell_type": "markdown",
   "metadata": {},
   "source": [
    "Hier wird der zweite Block nicht ausgeführt: Das liegt daran, dass der erste Block keinen Fehler zurückgegeben hat.\n",
    "Wir wollen nun eine problematische Anweisung in den ``try``-Block einfügen und sehen, was passiert:"
   ]
  },
  {
   "cell_type": "code",
   "execution_count": 4,
   "metadata": {
    "collapsed": false
   },
   "outputs": [
    {
     "name": "stdout",
     "output_type": "stream",
     "text": [
      "let's try something:\n",
      "something bad happened!\n"
     ]
    }
   ],
   "source": [
    "try:\n",
    "    print(\"let's try something:\")\n",
    "    x = 1 / 0 # ZeroDivisionError\n",
    "except:\n",
    "    print(\"something bad happened!\")"
   ]
  },
  {
   "cell_type": "markdown",
   "metadata": {},
   "source": [
    "Wir sehen hier, dass der Fehler, der in der ``try``-Anweisung ausgelöst wurde (in diesem Fall ein ``ZeroDivisionError``), abgefangen und die ``except``-Anweisung ausgeführt wurde.\n",
    "\n",
    "Eine häufige Anwendung ist die Überprüfung von Benutzereingaben innerhalb einer Funktion oder eines anderen Codeteils. Wir könnten zum Beispiel eine Funktion erschaffen, die eine Null-Division abfängt und einen anderen Wert zurückgibt, vielleicht eine SEHR große Zahl wie $10^{100}$:"
   ]
  },
  {
   "cell_type": "code",
   "execution_count": 5,
   "metadata": {
    "collapsed": false
   },
   "outputs": [],
   "source": [
    "def safe_divide(a, b):\n",
    "    try:\n",
    "        return a / b\n",
    "    except:\n",
    "        return 1E100"
   ]
  },
  {
   "cell_type": "code",
   "execution_count": 10,
   "metadata": {
    "collapsed": false
   },
   "outputs": [
    {
     "data": {
      "text/plain": [
       "0.5"
      ]
     },
     "execution_count": 10,
     "metadata": {},
     "output_type": "execute_result"
    }
   ],
   "source": [
    "safe_divide(1, 2)"
   ]
  },
  {
   "cell_type": "code",
   "execution_count": 6,
   "metadata": {
    "collapsed": false
   },
   "outputs": [
    {
     "data": {
      "text/plain": [
       "1e+100"
      ]
     },
     "execution_count": 6,
     "metadata": {},
     "output_type": "execute_result"
    }
   ],
   "source": [
    "safe_divide(2, 0)"
   ]
  },
  {
   "cell_type": "markdown",
   "metadata": {},
   "source": [
    "Allerdings gibt es ein kleines Problem mit diesem Code: Was passiert, wenn eine andere Art von Ausnahme auftritt? Dies ist zum Beispiel wahrscheinlich nicht das, was wir beabsichtigt haben:"
   ]
  },
  {
   "cell_type": "code",
   "execution_count": 7,
   "metadata": {
    "collapsed": false
   },
   "outputs": [
    {
     "data": {
      "text/plain": [
       "1e+100"
      ]
     },
     "execution_count": 7,
     "metadata": {},
     "output_type": "execute_result"
    }
   ],
   "source": [
    "safe_divide (1, '2') # Zeichenkette als Divisor"
   ]
  },
  {
   "cell_type": "markdown",
   "metadata": {},
   "source": [
    "Dividing an integer and a string raises a ``TypeError``, which our over-zealous code caught and assumed was a ``ZeroDivisionError``!\n",
    "For this reason, it's nearly always a better idea to catch exceptions *explicitly*:"
   ]
  },
  {
   "cell_type": "code",
   "execution_count": 8,
   "metadata": {
    "collapsed": false
   },
   "outputs": [],
   "source": [
    "def safe_divide(a, b):\n",
    "    try:\n",
    "        return a / b\n",
    "    except ZeroDivisionError:\n",
    "        return 1E100"
   ]
  },
  {
   "cell_type": "code",
   "execution_count": 9,
   "metadata": {
    "collapsed": false
   },
   "outputs": [
    {
     "data": {
      "text/plain": [
       "1e+100"
      ]
     },
     "execution_count": 9,
     "metadata": {},
     "output_type": "execute_result"
    }
   ],
   "source": [
    "safe_divide(1, 0)"
   ]
  },
  {
   "cell_type": "code",
   "execution_count": 10,
   "metadata": {
    "collapsed": false
   },
   "outputs": [
    {
     "ename": "TypeError",
     "evalue": "unsupported operand type(s) for /: 'int' and 'str'",
     "output_type": "error",
     "traceback": [
      "\u001b[0;31m---------------------------------------------------------------------------\u001b[0m",
      "\u001b[0;31mTypeError\u001b[0m                                 Traceback (most recent call last)",
      "Cell \u001b[0;32mIn[10], line 1\u001b[0m\n\u001b[0;32m----> 1\u001b[0m \u001b[43msafe_divide\u001b[49m\u001b[43m(\u001b[49m\u001b[38;5;241;43m1\u001b[39;49m\u001b[43m,\u001b[49m\u001b[43m \u001b[49m\u001b[38;5;124;43m'\u001b[39;49m\u001b[38;5;124;43m2\u001b[39;49m\u001b[38;5;124;43m'\u001b[39;49m\u001b[43m)\u001b[49m\n",
      "Cell \u001b[0;32mIn[8], line 3\u001b[0m, in \u001b[0;36msafe_divide\u001b[0;34m(a, b)\u001b[0m\n\u001b[1;32m      1\u001b[0m \u001b[38;5;28;01mdef\u001b[39;00m \u001b[38;5;21msafe_divide\u001b[39m(a, b):\n\u001b[1;32m      2\u001b[0m     \u001b[38;5;28;01mtry\u001b[39;00m:\n\u001b[0;32m----> 3\u001b[0m         \u001b[38;5;28;01mreturn\u001b[39;00m \u001b[43ma\u001b[49m\u001b[43m \u001b[49m\u001b[38;5;241;43m/\u001b[39;49m\u001b[43m \u001b[49m\u001b[43mb\u001b[49m\n\u001b[1;32m      4\u001b[0m     \u001b[38;5;28;01mexcept\u001b[39;00m \u001b[38;5;167;01mZeroDivisionError\u001b[39;00m:\n\u001b[1;32m      5\u001b[0m         \u001b[38;5;28;01mreturn\u001b[39;00m \u001b[38;5;241m1E100\u001b[39m\n",
      "\u001b[0;31mTypeError\u001b[0m: unsupported operand type(s) for /: 'int' and 'str'"
     ]
    }
   ],
   "source": [
    "safe_divide(1, '2')"
   ]
  },
  {
   "cell_type": "markdown",
   "metadata": {},
   "source": [
    "Wir fangen jetzt nur noch Null-Divisions-Fehler ab und reichen alle anderen Fehler unverändert weiter."
   ]
  },
  {
   "cell_type": "markdown",
   "metadata": {},
   "source": [
    "## Ausnahmen auslösen: ``raise``\n",
    "Wir haben gesehen, wie wertvoll es ist, informative Fehlermeldungen zu erhalten, wenn man eigenen oder fremden Code aufruft.\n",
    "Genauso wertvoll ist es, informative Fehlermeldungen in dem von uns geschriebenen Code zu erzeugen, so dass die Benutzer unseres Codes (einschließlich uns selbst!) herausfinden können, was die Fehler verursacht hat.\n",
    "\n",
    "Wir lösen unsere eigenen Ausnahmen mit der Anweisung ``raise`` aus. Zum Beispiel:"
   ]
  },
  {
   "cell_type": "code",
   "execution_count": 11,
   "metadata": {
    "collapsed": false
   },
   "outputs": [
    {
     "ename": "RuntimeError",
     "evalue": "my error message",
     "output_type": "error",
     "traceback": [
      "\u001b[0;31m---------------------------------------------------------------------------\u001b[0m",
      "\u001b[0;31mRuntimeError\u001b[0m                              Traceback (most recent call last)",
      "Cell \u001b[0;32mIn[11], line 1\u001b[0m\n\u001b[0;32m----> 1\u001b[0m \u001b[38;5;28;01mraise\u001b[39;00m \u001b[38;5;167;01mRuntimeError\u001b[39;00m(\u001b[38;5;124m\"\u001b[39m\u001b[38;5;124mmy error message\u001b[39m\u001b[38;5;124m\"\u001b[39m)\n",
      "\u001b[0;31mRuntimeError\u001b[0m: my error message"
     ]
    }
   ],
   "source": [
    "raise RuntimeError(\"my error message\")"
   ]
  },
  {
   "cell_type": "markdown",
   "metadata": {},
   "source": [
    "Als Beispiel dafür, wo dies nützlich sein könnte, kehren wir zu unserer ``fibonacci``-Funktion zurück, die wir zuvor definiert haben:"
   ]
  },
  {
   "cell_type": "code",
   "execution_count": 12,
   "metadata": {
    "collapsed": false
   },
   "outputs": [],
   "source": [
    "def fibonacci(N):\n",
    "    L = []\n",
    "    a, b = 0, 1\n",
    "    while len(L) < N:\n",
    "        a, b = b, a + b\n",
    "        L.append(a)\n",
    "    return L"
   ]
  },
  {
   "cell_type": "markdown",
   "metadata": {},
   "source": [
    "Ein mögliches Problem ist, dass der übergebene Eingabewert negativ sein könnte.\n",
    "Dies wird derzeit keinen Fehler in unserer Funktion auslösen, aber wir sollten den Benutzer wissen lassen, dass ein negatives ``N`` nicht unterstützt wird.\n",
    "Fehler, die auf ungültige Parameterwerte zurückzuführen sind, führen gemäß der Konvention zu einem ``ValueError``:"
   ]
  },
  {
   "cell_type": "code",
   "execution_count": 13,
   "metadata": {
    "collapsed": false
   },
   "outputs": [],
   "source": [
    "def fibonacci(N):\n",
    "    if N < 0:\n",
    "        raise ValueError(f\"N was {N}, but must be non-negative!\")\n",
    "    L = []\n",
    "    a, b = 0, 1\n",
    "    while len(L) < N:\n",
    "        a, b = b, a + b\n",
    "        L.append(a)\n",
    "    return L"
   ]
  },
  {
   "cell_type": "code",
   "execution_count": 14,
   "metadata": {
    "collapsed": false
   },
   "outputs": [
    {
     "data": {
      "text/plain": [
       "[1, 1, 2, 3, 5, 8, 13, 21, 34, 55]"
      ]
     },
     "execution_count": 14,
     "metadata": {},
     "output_type": "execute_result"
    }
   ],
   "source": [
    "fibonacci(10)"
   ]
  },
  {
   "cell_type": "code",
   "execution_count": 15,
   "metadata": {
    "collapsed": false
   },
   "outputs": [
    {
     "ename": "ValueError",
     "evalue": "N was -10, but must be non-negative!",
     "output_type": "error",
     "traceback": [
      "\u001b[0;31m---------------------------------------------------------------------------\u001b[0m",
      "\u001b[0;31mValueError\u001b[0m                                Traceback (most recent call last)",
      "Cell \u001b[0;32mIn[15], line 1\u001b[0m\n\u001b[0;32m----> 1\u001b[0m \u001b[43mfibonacci\u001b[49m\u001b[43m(\u001b[49m\u001b[38;5;241;43m-\u001b[39;49m\u001b[38;5;241;43m10\u001b[39;49m\u001b[43m)\u001b[49m\n",
      "Cell \u001b[0;32mIn[13], line 3\u001b[0m, in \u001b[0;36mfibonacci\u001b[0;34m(N)\u001b[0m\n\u001b[1;32m      1\u001b[0m \u001b[38;5;28;01mdef\u001b[39;00m \u001b[38;5;21mfibonacci\u001b[39m(N):\n\u001b[1;32m      2\u001b[0m     \u001b[38;5;28;01mif\u001b[39;00m N \u001b[38;5;241m<\u001b[39m \u001b[38;5;241m0\u001b[39m:\n\u001b[0;32m----> 3\u001b[0m         \u001b[38;5;28;01mraise\u001b[39;00m \u001b[38;5;167;01mValueError\u001b[39;00m(\u001b[38;5;124mf\u001b[39m\u001b[38;5;124m\"\u001b[39m\u001b[38;5;124mN was \u001b[39m\u001b[38;5;132;01m{\u001b[39;00mN\u001b[38;5;132;01m}\u001b[39;00m\u001b[38;5;124m, but must be non-negative!\u001b[39m\u001b[38;5;124m\"\u001b[39m)\n\u001b[1;32m      4\u001b[0m     L \u001b[38;5;241m=\u001b[39m []\n\u001b[1;32m      5\u001b[0m     a, b \u001b[38;5;241m=\u001b[39m \u001b[38;5;241m0\u001b[39m, \u001b[38;5;241m1\u001b[39m\n",
      "\u001b[0;31mValueError\u001b[0m: N was -10, but must be non-negative!"
     ]
    }
   ],
   "source": [
    "fibonacci(-10)"
   ]
  },
  {
   "cell_type": "markdown",
   "metadata": {},
   "source": [
    "Jetzt wissen die alle, die unseren Code nutzen, genau, warum die Eingabe ungültig ist, und können sogar einen ``try``...``except``-Block verwenden, um das Problem zu lösen!"
   ]
  },
  {
   "cell_type": "code",
   "execution_count": 16,
   "metadata": {
    "collapsed": false
   },
   "outputs": [
    {
     "name": "stdout",
     "output_type": "stream",
     "text": [
      "trying this...\n",
      "Bad value: need to do something else\n"
     ]
    }
   ],
   "source": [
    "N = -10\n",
    "try:\n",
    "    print(\"trying this...\")\n",
    "    print(fibonacci(N))\n",
    "except ValueError: # NICHT optimal! (siehe unten)\n",
    "    print(\"Bad value: need to do something else\")"
   ]
  },
  {
   "cell_type": "markdown",
   "metadata": {},
   "source": [
    "## Wir tauchen tiefer in die Ausnahmen ein...\n",
    "\n",
    "Wir wollen uns noch einige Konzepte anschauen, die uns in Beispielcode begegnen könnten, ohne dabei auf jedes letzte Detail einzugehen. Wir machen uns mit der Syntax vertraut, wer möchte kann die Konzepte selbst weiter erkunden."
   ]
  },
  {
   "cell_type": "markdown",
   "metadata": {},
   "source": [
    "### Zugriff auf die Fehlermeldung\n",
    "\n",
    "Manchmal möchte man in einer ``try``...``except``-Anweisung mit der Fehlermeldung selbst arbeiten. Dies kann mit dem ``as``-Schlüsselwort erreicht werden:"
   ]
  },
  {
   "cell_type": "code",
   "execution_count": 17,
   "metadata": {
    "collapsed": false
   },
   "outputs": [
    {
     "name": "stdout",
     "output_type": "stream",
     "text": [
      "Error class is:   <class 'ZeroDivisionError'>\n",
      "Error message is: division by zero\n"
     ]
    }
   ],
   "source": [
    "try:\n",
    "    x = 1 / 0\n",
    "except ZeroDivisionError as err:\n",
    "    print(\"Error class is:  \", type(err))\n",
    "    print(\"Error message is:\", err)"
   ]
  },
  {
   "cell_type": "markdown",
   "metadata": {},
   "source": [
    "Mit diesem Muster können wir die Behandlung von Ausnahmen in unseren Funktionen weiter anpassen."
   ]
  },
  {
   "cell_type": "markdown",
   "metadata": {},
   "source": [
    "### Definition von benutzerdefinierten Ausnahmen\n",
    "\n",
    "Zusätzlich zu den eingebauten Ausnahmen können wir unsere eigenen Ausnahmen durch *Vererbungsbeziehungen* definieren.\n",
    "Wenn wir zum Beispiel eine spezielle Art von ``ValueError`` haben wollen, können wir dies tun:"
   ]
  },
  {
   "cell_type": "code",
   "execution_count": 23,
   "metadata": {
    "collapsed": false
   },
   "outputs": [
    {
     "ename": "MySpecialError",
     "evalue": "here's the message",
     "output_type": "error",
     "traceback": [
      "\u001b[0;31m---------------------------------------------------------------------------\u001b[0m",
      "\u001b[0;31mMySpecialError\u001b[0m                            Traceback (most recent call last)",
      "\u001b[0;32m<ipython-input-23-92c36e04a9d0>\u001b[0m in \u001b[0;36m<module>\u001b[0;34m()\u001b[0m\n\u001b[1;32m      2\u001b[0m     \u001b[0;32mpass\u001b[0m\u001b[0;34m\u001b[0m\u001b[0m\n\u001b[1;32m      3\u001b[0m \u001b[0;34m\u001b[0m\u001b[0m\n\u001b[0;32m----> 4\u001b[0;31m \u001b[0;32mraise\u001b[0m \u001b[0mMySpecialError\u001b[0m\u001b[0;34m(\u001b[0m\u001b[0;34m\"here's the message\"\u001b[0m\u001b[0;34m)\u001b[0m\u001b[0;34m\u001b[0m\u001b[0m\n\u001b[0m",
      "\u001b[0;31mMySpecialError\u001b[0m: here's the message"
     ]
    }
   ],
   "source": [
    "class MySpecialError(ValueError):\n",
    "    pass\n",
    "\n",
    "raise MySpecialError(\"here's the message\")"
   ]
  },
  {
   "cell_type": "markdown",
   "metadata": {},
   "source": [
    "Dies würde es uns ermöglichen, einen ``try``...``except``-Block zu verwenden, der nur diese Art von Fehler abfängt:"
   ]
  },
  {
   "cell_type": "code",
   "execution_count": 24,
   "metadata": {
    "collapsed": false
   },
   "outputs": [
    {
     "name": "stdout",
     "output_type": "stream",
     "text": [
      "do something\n",
      "do something else\n"
     ]
    }
   ],
   "source": [
    "try:\n",
    "    print(\"do something\")\n",
    "    raise MySpecialError(\"[informative error message here]\")\n",
    "except MySpecialError:\n",
    "    print(\"do something else\")"
   ]
  },
  {
   "cell_type": "markdown",
   "metadata": {},
   "source": [
    "Dies könnte sich als nützlich erweisen, wenn wir mehr eigenen Code entwickeln."
   ]
  },
  {
   "cell_type": "markdown",
   "metadata": {},
   "source": [
    "## ``try``...``except``...``else``...``finally``\n",
    "Zusätzlich zu den Schlüsselwörtern ``try`` und ``except`` können wir die Schlüsselwörter ``else`` und ``finally`` verwenden, um die Behandlung von Ausnahmen in unserem Code weiter zu optimieren.\n",
    "Die grundlegende Struktur ist die folgende:"
   ]
  },
  {
   "cell_type": "code",
   "execution_count": 25,
   "metadata": {
    "collapsed": false
   },
   "outputs": [
    {
     "name": "stdout",
     "output_type": "stream",
     "text": [
      "try something here\n",
      "this happens only if it succeeds\n",
      "this happens no matter what\n"
     ]
    }
   ],
   "source": [
    "try:\n",
    "    print(\"try something here\")\n",
    "except:\n",
    "    print(\"this happens only if it fails\")\n",
    "else:\n",
    "    print(\"this happens only if it succeeds\")\n",
    "finally:\n",
    "    print(\"this happens no matter what\")"
   ]
  },
  {
   "cell_type": "markdown",
   "metadata": {},
   "source": [
    "Der Nutzen von ``else`` ist hier klar, aber was ist der Sinn von ``finally``?\n",
    "Die ``finally``-Klausel wird wirklich *IMMER* ausgeführt: Normalerweise wird sie verwendet, um eine Aufräumajktionen nach Abschluss einer Operation durchzuführen."
   ]
  }
 ],
 "metadata": {
  "anaconda-cloud": {},
  "kernelspec": {
   "display_name": "Python 3",
   "language": "python",
   "name": "python3"
  },
  "language_info": {
   "codemirror_mode": {
    "name": "ipython",
    "version": 3
   },
   "file_extension": ".py",
   "mimetype": "text/x-python",
   "name": "python",
   "nbconvert_exporter": "python",
   "pygments_lexer": "ipython3",
   "version": "3.12.3"
  }
 },
 "nbformat": 4,
 "nbformat_minor": 0
}
